Workbook

Sheet 00_BAT_DAU
B2: MINGO | C2: MINGO | D2: MINGO | E2: MINGO | F2: MINGO | G2: MINGO | H2: MINGO | I2: MINGO | J2: MINGO | K2: MINGO | L2: MINGO
B3: MINGO | C3: MINGO | D3: MINGO | E3: MINGO | F3: MINGO | G3: MINGO | H3: MINGO | I3: MINGO | J3: MINGO | K3: MINGO | L3: MINGO
B4: Quản lý dự án / Từ ý tưởng đến sản phẩm | C4: Quản lý dự án / Từ ý tưởng đến sản phẩm | D4: Quản lý dự án / Từ ý tưởng đến sản phẩm | E4: Quản lý dự án / Từ ý tưởng đến sản phẩm | F4: Quản lý dự án / Từ ý tưởng đến sản phẩm | G4: Quản lý dự án / Từ ý tưởng đến sản phẩm | H4: Quản lý dự án / Từ ý tưởng đến sản phẩm | I4: Quản lý dự án / Từ ý tưởng đến sản phẩm | J4: Quản lý dự án / Từ ý tưởng đến sản phẩm | K4: Quản lý dự án / Từ ý tưởng đến sản phẩm | L4: Quản lý dự án / Từ ý tưởng đến sản phẩm | M4: Quản lý dự án / Từ ý tưởng đến sản phẩm | N4: Quản lý dự án / Từ ý tưởng đến sản phẩm | O4: Quản lý dự án / Từ ý tưởng đến sản phẩm | P4: Quản lý dự án / Từ ý tưởng đến sản phẩm | Q4: Quản lý dự án / Từ ý tưởng đến sản phẩm | R4: Quản lý dự án / Từ ý tưởng đến sản phẩm
B6: Workbook này có 7 sheet. Mỗi sheet trả lời đúng một câu hỏi. Nếu mới vào dự án, đọc sheet này → 01_TONG_QUAN → 02_SAN_PHAM trước khi code. | C6: Workbook này có 7 sheet. Mỗi sheet trả lời đúng một câu hỏi. Nếu mới vào dự án, đọc sheet này → 01_TONG_QUAN → 02_SAN_PHAM trước khi code. | D6: Workbook này có 7 sheet. Mỗi sheet trả lời đúng một câu hỏi. Nếu mới vào dự án, đọc sheet này → 01_TONG_QUAN → 02_SAN_PHAM trước khi code. | E6: Workbook này có 7 sheet. Mỗi sheet trả lời đúng một câu hỏi. Nếu mới vào dự án, đọc sheet này → 01_TONG_QUAN → 02_SAN_PHAM trước khi code. | F6: Workbook này có 7 sheet. Mỗi sheet trả lời đúng một câu hỏi. Nếu mới vào dự án, đọc sheet này → 01_TONG_QUAN → 02_SAN_PHAM trước khi code. | G6: Workbook này có 7 sheet. Mỗi sheet trả lời đúng một câu hỏi. Nếu mới vào dự án, đọc sheet này → 01_TONG_QUAN → 02_SAN_PHAM trước khi code. | H6: Workbook này có 7 sheet. Mỗi sheet trả lời đúng một câu hỏi. Nếu mới vào dự án, đọc sheet này → 01_TONG_QUAN → 02_SAN_PHAM trước khi code. | I6: Workbook này có 7 sheet. Mỗi sheet trả lời đúng một câu hỏi. Nếu mới vào dự án, đọc sheet này → 01_TONG_QUAN → 02_SAN_PHAM trước khi code. | J6: Workbook này có 7 sheet. Mỗi sheet trả lời đúng một câu hỏi. Nếu mới vào dự án, đọc sheet này → 01_TONG_QUAN → 02_SAN_PHAM trước khi code. | K6: Workbook này có 7 sheet. Mỗi sheet trả lời đúng một câu hỏi. Nếu mới vào dự án, đọc sheet này → 01_TONG_QUAN → 02_SAN_PHAM trước khi code. | L6: Workbook này có 7 sheet. Mỗi sheet trả lời đúng một câu hỏi. Nếu mới vào dự án, đọc sheet này → 01_TONG_QUAN → 02_SAN_PHAM trước khi code. | M6: Workbook này có 7 sheet. Mỗi sheet trả lời đúng một câu hỏi. Nếu mới vào dự án, đọc sheet này → 01_TONG_QUAN → 02_SAN_PHAM trước khi code. | N6: Workbook này có 7 sheet. Mỗi sheet trả lời đúng một câu hỏi. Nếu mới vào dự án, đọc sheet này → 01_TONG_QUAN → 02_SAN_PHAM trước khi code. | O6: Workbook này có 7 sheet. Mỗi sheet trả lời đúng một câu hỏi. Nếu mới vào dự án, đọc sheet này → 01_TONG_QUAN → 02_SAN_PHAM trước khi code. | P6: Workbook này có 7 sheet. Mỗi sheet trả lời đúng một câu hỏi. Nếu mới vào dự án, đọc sheet này → 01_TONG_QUAN → 02_SAN_PHAM trước khi code. | Q6: Workbook này có 7 sheet. Mỗi sheet trả lời đúng một câu hỏi. Nếu mới vào dự án, đọc sheet này → 01_TONG_QUAN → 02_SAN_PHAM trước khi code. | R6: Workbook này có 7 sheet. Mỗi sheet trả lời đúng một câu hỏi. Nếu mới vào dự án, đọc sheet này → 01_TONG_QUAN → 02_SAN_PHAM trước khi code.
B7: Workbook này có 7 sheet. Mỗi sheet trả lời đúng một câu hỏi. Nếu mới vào dự án, đọc sheet này → 01_TONG_QUAN → 02_SAN_PHAM trước khi code. | C7: Workbook này có 7 sheet. Mỗi sheet trả lời đúng một câu hỏi. Nếu mới vào dự án, đọc sheet này → 01_TONG_QUAN → 02_SAN_PHAM trước khi code. | D7: Workbook này có 7 sheet. Mỗi sheet trả lời đúng một câu hỏi. Nếu mới vào dự án, đọc sheet này → 01_TONG_QUAN → 02_SAN_PHAM trước khi code. | E7: Workbook này có 7 sheet. Mỗi sheet trả lời đúng một câu hỏi. Nếu mới vào dự án, đọc sheet này → 01_TONG_QUAN → 02_SAN_PHAM trước khi code. | F7: Workbook này có 7 sheet. Mỗi sheet trả lời đúng một câu hỏi. Nếu mới vào dự án, đọc sheet này → 01_TONG_QUAN → 02_SAN_PHAM trước khi code. | G7: Workbook này có 7 sheet. Mỗi sheet trả lời đúng một câu hỏi. Nếu mới vào dự án, đọc sheet này → 01_TONG_QUAN → 02_SAN_PHAM trước khi code. | H7: Workbook này có 7 sheet. Mỗi sheet trả lời đúng một câu hỏi. Nếu mới vào dự án, đọc sheet này → 01_TONG_QUAN → 02_SAN_PHAM trước khi code. | I7: Workbook này có 7 sheet. Mỗi sheet trả lời đúng một câu hỏi. Nếu mới vào dự án, đọc sheet này → 01_TONG_QUAN → 02_SAN_PHAM trước khi code. | J7: Workbook này có 7 sheet. Mỗi sheet trả lời đúng một câu hỏi. Nếu mới vào dự án, đọc sheet này → 01_TONG_QUAN → 02_SAN_PHAM trước khi code. | K7: Workbook này có 7 sheet. Mỗi sheet trả lời đúng một câu hỏi. Nếu mới vào dự án, đọc sheet này → 01_TONG_QUAN → 02_SAN_PHAM trước khi code. | L7: Workbook này có 7 sheet. Mỗi sheet trả lời đúng một câu hỏi. Nếu mới vào dự án, đọc sheet này → 01_TONG_QUAN → 02_SAN_PHAM trước khi code. | M7: Workbook này có 7 sheet. Mỗi sheet trả lời đúng một câu hỏi. Nếu mới vào dự án, đọc sheet này → 01_TONG_QUAN → 02_SAN_PHAM trước khi code. | N7: Workbook này có 7 sheet. Mỗi sheet trả lời đúng một câu hỏi. Nếu mới vào dự án, đọc sheet này → 01_TONG_QUAN → 02_SAN_PHAM trước khi code. | O7: Workbook này có 7 sheet. Mỗi sheet trả lời đúng một câu hỏi. Nếu mới vào dự án, đọc sheet này → 01_TONG_QUAN → 02_SAN_PHAM trước khi code. | P7: Workbook này có 7 sheet. Mỗi sheet trả lời đúng một câu hỏi. Nếu mới vào dự án, đọc sheet này → 01_TONG_QUAN → 02_SAN_PHAM trước khi code. | Q7: Workbook này có 7 sheet. Mỗi sheet trả lời đúng một câu hỏi. Nếu mới vào dự án, đọc sheet này → 01_TONG_QUAN → 02_SAN_PHAM trước khi code. | R7: Workbook này có 7 sheet. Mỗi sheet trả lời đúng một câu hỏi. Nếu mới vào dự án, đọc sheet này → 01_TONG_QUAN → 02_SAN_PHAM trước khi code.
B9: 01 Tổng quan | C9: 01 Tổng quan | D9: 01 Tổng quan | E9: 01 Tổng quan | F9: 01 Tổng quan | H9: 02 Sản phẩm | I9: 02 Sản phẩm | J9: 02 Sản phẩm | K9: 02 Sản phẩm | L9: 02 Sản phẩm | N9: 03 Roadmap | O9: 03 Roadmap | P9: 03 Roadmap | Q9: 03 Roadmap | R9: 03 Roadmap
B10: Xem phase hiện tại, blocker, tiến độ Phase 1 và thứ tự việc tiếp theo. | C10: Xem phase hiện tại, blocker, tiến độ Phase 1 và thứ tự việc tiếp theo. | D10: Xem phase hiện tại, blocker, tiến độ Phase 1 và thứ tự việc tiếp theo. | E10: Xem phase hiện tại, blocker, tiến độ Phase 1 và thứ tự việc tiếp theo. | F10: Xem phase hiện tại, blocker, tiến độ Phase 1 và thứ tự việc tiếp theo. | H10: Hiểu luồng learner, luật dễ làm sai, nội dung đã chốt/chưa chốt, V3.2. | I10: Hiểu luồng learner, luật dễ làm sai, nội dung đã chốt/chưa chốt, V3.2. | J10: Hiểu luồng learner, luật dễ làm sai, nội dung đã chốt/chưa chốt, V3.2. | K10: Hiểu luồng learner, luật dễ làm sai, nội dung đã chốt/chưa chốt, V3.2. | L10: Hiểu luồng learner, luật dễ làm sai, nội dung đã chốt/chưa chốt, V3.2. | N10: Xem mục tiêu từng phase và checklist Phase 1 được đồng bộ từ Task. | O10: Xem mục tiêu từng phase và checklist Phase 1 được đồng bộ từ Task. | P10: Xem mục tiêu từng phase và checklist Phase 1 được đồng bộ từ Task. | Q10: Xem mục tiêu từng phase và checklist Phase 1 được đồng bộ từ Task. | R10: Xem mục tiêu từng phase và checklist Phase 1 được đồng bộ từ Task.
B11: Xem phase hiện tại, blocker, tiến độ Phase 1 và thứ tự việc tiếp theo. | C11: Xem phase hiện tại, blocker, tiến độ Phase 1 và thứ tự việc tiếp theo. | D11: Xem phase hiện tại, blocker, tiến độ Phase 1 và thứ tự việc tiếp theo. | E11: Xem phase hiện tại, blocker, tiến độ Phase 1 và thứ tự việc tiếp theo. | F11: Xem phase hiện tại, blocker, tiến độ Phase 1 và thứ tự việc tiếp theo. | H11: Hiểu luồng learner, luật dễ làm sai, nội dung đã chốt/chưa chốt, V3.2. | I11: Hiểu luồng learner, luật dễ làm sai, nội dung đã chốt/chưa chốt, V3.2. | J11: Hiểu luồng learner, luật dễ làm sai, nội dung đã chốt/chưa chốt, V3.2. | K11: Hiểu luồng learner, luật dễ làm sai, nội dung đã chốt/chưa chốt, V3.2. | L11: Hiểu luồng learner, luật dễ làm sai, nội dung đã chốt/chưa chốt, V3.2. | N11: Xem mục tiêu từng phase và checklist Phase 1 được đồng bộ từ Task. | O11: Xem mục tiêu từng phase và checklist Phase 1 được đồng bộ từ Task. | P11: Xem mục tiêu từng phase và checklist Phase 1 được đồng bộ từ Task. | Q11: Xem mục tiêu từng phase và checklist Phase 1 được đồng bộ từ Task. | R11: Xem mục tiêu từng phase và checklist Phase 1 được đồng bộ từ Task.
B12: Xem phase hiện tại, blocker, tiến độ Phase 1 và thứ tự việc tiếp theo. | C12: Xem phase hiện tại, blocker, tiến độ Phase 1 và thứ tự việc tiếp theo. | D12: Xem phase hiện tại, blocker, tiến độ Phase 1 và thứ tự việc tiếp theo. | E12: Xem phase hiện tại, blocker, tiến độ Phase 1 và thứ tự việc tiếp theo. | F12: Xem phase hiện tại, blocker, tiến độ Phase 1 và thứ tự việc tiếp theo. | H12: Hiểu luồng learner, luật dễ làm sai, nội dung đã chốt/chưa chốt, V3.2. | I12: Hiểu luồng learner, luật dễ làm sai, nội dung đã chốt/chưa chốt, V3.2. | J12: Hiểu luồng learner, luật dễ làm sai, nội dung đã chốt/chưa chốt, V3.2. | K12: Hiểu luồng learner, luật dễ làm sai, nội dung đã chốt/chưa chốt, V3.2. | L12: Hiểu luồng learner, luật dễ làm sai, nội dung đã chốt/chưa chốt, V3.2. | N12: Xem mục tiêu từng phase và checklist Phase 1 được đồng bộ từ Task. | O12: Xem mục tiêu từng phase và checklist Phase 1 được đồng bộ từ Task. | P12: Xem mục tiêu từng phase và checklist Phase 1 được đồng bộ từ Task. | Q12: Xem mục tiêu từng phase và checklist Phase 1 được đồng bộ từ Task. | R12: Xem mục tiêu từng phase và checklist Phase 1 được đồng bộ từ Task.
B13: Owner / Lead / Team | C13: Owner / Lead / Team | D13: Owner / Lead / Team | E13: Owner / Lead / Team | F13: Owner / Lead / Team | H13: Tất cả mọi người | I13: Tất cả mọi người | J13: Tất cả mọi người | K13: Tất cả mọi người | L13: Tất cả mọi người | N13: Owner / Lead | O13: Owner / Lead | P13: Owner / Lead | Q13: Owner / Lead | R13: Owner / Lead
B14: =HYPERLINK("#'01_TONG_QUAN'!A1","Mở Tổng quan →") -> Mở Tổng quan → | H14: =HYPERLINK("#'02_SAN_PHAM'!A1","Mở Sản phẩm →") -> Mở Sản phẩm → | N14: =HYPERLINK("#'03_ROADMAP'!A1","Mở Roadmap →") -> Mở Roadmap →
B17: 04 Công việc | C17: 04 Công việc | D17: 04 Công việc | E17: 04 Công việc | F17: 04 Công việc | H17: 05 Vấn đề / Thay đổi | I17: 05 Vấn đề / Thay đổi | J17: 05 Vấn đề / Thay đổi | K17: 05 Vấn đề / Thay đổi | L17: 05 Vấn đề / Thay đổi | N17: 06 Bằng chứng | O17: 06 Bằng chứng | P17: 06 Bằng chứng | Q17: 06 Bằng chứng | R17: 06 Bằng chứng
B18: Sheet team dùng hằng ngày: người phụ trách, người kiểm tra, hạn, việc tiếp theo, bằng chứng, ghi chú. | C18: Sheet team dùng hằng ngày: người phụ trách, người kiểm tra, hạn, việc tiếp theo, bằng chứng, ghi chú. | D18: Sheet team dùng hằng ngày: người phụ trách, người kiểm tra, hạn, việc tiếp theo, bằng chứng, ghi chú. | E18: Sheet team dùng hằng ngày: người phụ trách, người kiểm tra, hạn, việc tiếp theo, bằng chứng, ghi chú. | F18: Sheet team dùng hằng ngày: người phụ trách, người kiểm tra, hạn, việc tiếp theo, bằng chứng, ghi chú. | H18: Issue kỹ thuật, đề nghị thay đổi nội dung đã chốt, note/action. | I18: Issue kỹ thuật, đề nghị thay đổi nội dung đã chốt, note/action. | J18: Issue kỹ thuật, đề nghị thay đổi nội dung đã chốt, note/action. | K18: Issue kỹ thuật, đề nghị thay đổi nội dung đã chốt, note/action. | L18: Issue kỹ thuật, đề nghị thay đổi nội dung đã chốt, note/action. | N18: Phân biệt PASS hiện tại, PASS lịch sử, chờ chạy và bị chặn. | O18: Phân biệt PASS hiện tại, PASS lịch sử, chờ chạy và bị chặn. | P18: Phân biệt PASS hiện tại, PASS lịch sử, chờ chạy và bị chặn. | Q18: Phân biệt PASS hiện tại, PASS lịch sử, chờ chạy và bị chặn. | R18: Phân biệt PASS hiện tại, PASS lịch sử, chờ chạy và bị chặn.
B19: Sheet team dùng hằng ngày: người phụ trách, người kiểm tra, hạn, việc tiếp theo, bằng chứng, ghi chú. | C19: Sheet team dùng hằng ngày: người phụ trách, người kiểm tra, hạn, việc tiếp theo, bằng chứng, ghi chú. | D19: Sheet team dùng hằng ngày: người phụ trách, người kiểm tra, hạn, việc tiếp theo, bằng chứng, ghi chú. | E19: Sheet team dùng hằng ngày: người phụ trách, người kiểm tra, hạn, việc tiếp theo, bằng chứng, ghi chú. | F19: Sheet team dùng hằng ngày: người phụ trách, người kiểm tra, hạn, việc tiếp theo, bằng chứng, ghi chú. | H19: Issue kỹ thuật, đề nghị thay đổi nội dung đã chốt, note/action. | I19: Issue kỹ thuật, đề nghị thay đổi nội dung đã chốt, note/action. | J19: Issue kỹ thuật, đề nghị thay đổi nội dung đã chốt, note/action. | K19: Issue kỹ thuật, đề nghị thay đổi nội dung đã chốt, note/action. | L19: Issue kỹ thuật, đề nghị thay đổi nội dung đã chốt, note/action. | N19: Phân biệt PASS hiện tại, PASS lịch sử, chờ chạy và bị chặn. | O19: Phân biệt PASS hiện tại, PASS lịch sử, chờ chạy và bị chặn. | P19: Phân biệt PASS hiện tại, PASS lịch sử, chờ chạy và bị chặn. | Q19: Phân biệt PASS hiện tại, PASS lịch sử, chờ chạy và bị chặn. | R19: Phân biệt PASS hiện tại, PASS lịch sử, chờ chạy và bị chặn.
B20: Sheet team dùng hằng ngày: người phụ trách, người kiểm tra, hạn, việc tiếp theo, bằng chứng, ghi chú. | C20: Sheet team dùng hằng ngày: người phụ trách, người kiểm tra, hạn, việc tiếp theo, bằng chứng, ghi chú. | D20: Sheet team dùng hằng ngày: người phụ trách, người kiểm tra, hạn, việc tiếp theo, bằng chứng, ghi chú. | E20: Sheet team dùng hằng ngày: người phụ trách, người kiểm tra, hạn, việc tiếp theo, bằng chứng, ghi chú. | F20: Sheet team dùng hằng ngày: người phụ trách, người kiểm tra, hạn, việc tiếp theo, bằng chứng, ghi chú. | H20: Issue kỹ thuật, đề nghị thay đổi nội dung đã chốt, note/action. | I20: Issue kỹ thuật, đề nghị thay đổi nội dung đã chốt, note/action. | J20: Issue kỹ thuật, đề nghị thay đổi nội dung đã chốt, note/action. | K20: Issue kỹ thuật, đề nghị thay đổi nội dung đã chốt, note/action. | L20: Issue kỹ thuật, đề nghị thay đổi nội dung đã chốt, note/action. | N20: Phân biệt PASS hiện tại, PASS lịch sử, chờ chạy và bị chặn. | O20: Phân biệt PASS hiện tại, PASS lịch sử, chờ chạy và bị chặn. | P20: Phân biệt PASS hiện tại, PASS lịch sử, chờ chạy và bị chặn. | Q20: Phân biệt PASS hiện tại, PASS lịch sử, chờ chạy và bị chặn. | R20: Phân biệt PASS hiện tại, PASS lịch sử, chờ chạy và bị chặn.
B21: Dev / QA / Content / Data | C21: Dev / QA / Content / Data | D21: Dev / QA / Content / Data | E21: Dev / QA / Content / Data | F21: Dev / QA / Content / Data | H21: Tất cả mọi người | I21: Tất cả mọi người | J21: Tất cả mọi người | K21: Tất cả mọi người | L21: Tất cả mọi người | N21: QA / Lead / Owner | O21: QA / Lead / Owner | P21: QA / Lead / Owner | Q21: QA / Lead / Owner | R21: QA / Lead / Owner
B22: =HYPERLINK("#'04_CONG_VIEC'!A1","Mở Công việc →") -> Mở Công việc → | H22: =HYPERLINK("#'05_VAN_DE_THAY_DOI'!A1","Mở Vấn đề / Thay đổi →") -> Mở Vấn đề / Thay đổi → | N22: =HYPERLINK("#'06_BANG_CHUNG'!A1","Mở Bằng chứng →") -> Mở Bằng chứng →
B26: 5 QUY TẮC LÀM VIỆC | C26: 5 QUY TẮC LÀM VIỆC | D26: 5 QUY TẮC LÀM VIỆC | E26: 5 QUY TẮC LÀM VIỆC | F26: 5 QUY TẮC LÀM VIỆC | G26: 5 QUY TẮC LÀM VIỆC | H26: 5 QUY TẮC LÀM VIỆC | I26: 5 QUY TẮC LÀM VIỆC | J26: 5 QUY TẮC LÀM VIỆC | K26: 5 QUY TẮC LÀM VIỆC | L26: 5 QUY TẮC LÀM VIỆC | M26: 5 QUY TẮC LÀM VIỆC | N26: 5 QUY TẮC LÀM VIỆC | O26: 5 QUY TẮC LÀM VIỆC | P26: 5 QUY TẮC LÀM VIỆC | Q26: 5 QUY TẮC LÀM VIỆC | R26: 5 QUY TẮC LÀM VIỆC
B27: 5 QUY TẮC LÀM VIỆC | C27: 5 QUY TẮC LÀM VIỆC | D27: 5 QUY TẮC LÀM VIỆC | E27: 5 QUY TẮC LÀM VIỆC | F27: 5 QUY TẮC LÀM VIỆC | G27: 5 QUY TẮC LÀM VIỆC | H27: 5 QUY TẮC LÀM VIỆC | I27: 5 QUY TẮC LÀM VIỆC | J27: 5 QUY TẮC LÀM VIỆC | K27: 5 QUY TẮC LÀM VIỆC | L27: 5 QUY TẮC LÀM VIỆC | M27: 5 QUY TẮC LÀM VIỆC | N27: 5 QUY TẮC LÀM VIỆC | O27: 5 QUY TẮC LÀM VIỆC | P27: 5 QUY TẮC LÀM VIỆC | Q27: 5 QUY TẮC LÀM VIỆC | R27: 5 QUY TẮC LÀM VIỆC
B28: 1 | C28: Không tự sửa nội dung đã chốt. | D28: Không tự sửa nội dung đã chốt. | E28: Không tự sửa nội dung đã chốt. | F28: Không tự sửa nội dung đã chốt. | G28: Không tự sửa nội dung đã chốt. | H28: Không tự sửa nội dung đã chốt. | I28: Muốn đổi kiến trúc/business rule đã khóa → tạo Đề nghị thay đổi (Change Request). | J28: Muốn đổi kiến trúc/business rule đã khóa → tạo Đề nghị thay đổi (Change Request). | K28: Muốn đổi kiến trúc/business rule đã khóa → tạo Đề nghị thay đổi (Change Request). | L28: Muốn đổi kiến trúc/business rule đã khóa → tạo Đề nghị thay đổi (Change Request). | M28: Muốn đổi kiến trúc/business rule đã khóa → tạo Đề nghị thay đổi (Change Request). | N28: Muốn đổi kiến trúc/business rule đã khóa → tạo Đề nghị thay đổi (Change Request). | O28: Muốn đổi kiến trúc/business rule đã khóa → tạo Đề nghị thay đổi (Change Request). | P28: Muốn đổi kiến trúc/business rule đã khóa → tạo Đề nghị thay đổi (Change Request). | Q28: Muốn đổi kiến trúc/business rule đã khóa → tạo Đề nghị thay đổi (Change Request). | R28: Muốn đổi kiến trúc/business rule đã khóa → tạo Đề nghị thay đổi (Change Request).
B29: 1 | C29: Không tự sửa nội dung đã chốt. | D29: Không tự sửa nội dung đã chốt. | E29: Không tự sửa nội dung đã chốt. | F29: Không tự sửa nội dung đã chốt. | G29: Không tự sửa nội dung đã chốt. | H29: Không tự sửa nội dung đã chốt. | I29: Muốn đổi kiến trúc/business rule đã khóa → tạo Đề nghị thay đổi (Change Request). | J29: Muốn đổi kiến trúc/business rule đã khóa → tạo Đề nghị thay đổi (Change Request). | K29: Muốn đổi kiến trúc/business rule đã khóa → tạo Đề nghị thay đổi (Change Request). | L29: Muốn đổi kiến trúc/business rule đã khóa → tạo Đề nghị thay đổi (Change Request). | M29: Muốn đổi kiến trúc/business rule đã khóa → tạo Đề nghị thay đổi (Change Request). | N29: Muốn đổi kiến trúc/business rule đã khóa → tạo Đề nghị thay đổi (Change Request). | O29: Muốn đổi kiến trúc/business rule đã khóa → tạo Đề nghị thay đổi (Change Request). | P29: Muốn đổi kiến trúc/business rule đã khóa → tạo Đề nghị thay đổi (Change Request). | Q29: Muốn đổi kiến trúc/business rule đã khóa → tạo Đề nghị thay đổi (Change Request). | R29: Muốn đổi kiến trúc/business rule đã khóa → tạo Đề nghị thay đổi (Change Request).
B30: 2 | C30: Không đánh XONG chỉ vì có code. | D30: Không đánh XONG chỉ vì có code. | E30: Không đánh XONG chỉ vì có code. | F30: Không đánh XONG chỉ vì có code. | G30: Không đánh XONG chỉ vì có code. | H30: Không đánh XONG chỉ vì có code. | I30: XONG phải có bằng chứng phù hợp: test, runtime, CI hoặc review theo gate. | J30: XONG phải có bằng chứng phù hợp: test, runtime, CI hoặc review theo gate. | K30: XONG phải có bằng chứng phù hợp: test, runtime, CI hoặc review theo gate. | L30: XONG phải có bằng chứng phù hợp: test, runtime, CI hoặc review theo gate. | M30: XONG phải có bằng chứng phù hợp: test, runtime, CI hoặc review theo gate. | N30: XONG phải có bằng chứng phù hợp: test, runtime, CI hoặc review theo gate. | O30: XONG phải có bằng chứng phù hợp: test, runtime, CI hoặc review theo gate. | P30: XONG phải có bằng chứng phù hợp: test, runtime, CI hoặc review theo gate. | Q30: XONG phải có bằng chứng phù hợp: test, runtime, CI hoặc review theo gate. | R30: XONG phải có bằng chứng phù hợp: test, runtime, CI hoặc review theo gate.
B31: 2 | C31: Không đánh XONG chỉ vì có code. | D31: Không đánh XONG chỉ vì có code. | E31: Không đánh XONG chỉ vì có code. | F31: Không đánh XONG chỉ vì có code. | G31: Không đánh XONG chỉ vì có code. | H31: Không đánh XONG chỉ vì có code. | I31: XONG phải có bằng chứng phù hợp: test, runtime, CI hoặc review theo gate. | J31: XONG phải có bằng chứng phù hợp: test, runtime, CI hoặc review theo gate. | K31: XONG phải có bằng chứng phù hợp: test, runtime, CI hoặc review theo gate. | L31: XONG phải có bằng chứng phù hợp: test, runtime, CI hoặc review theo gate. | M31: XONG phải có bằng chứng phù hợp: test, runtime, CI hoặc review theo gate. | N31: XONG phải có bằng chứng phù hợp: test, runtime, CI hoặc review theo gate. | O31: XONG phải có bằng chứng phù hợp: test, runtime, CI hoặc review theo gate. | P31: XONG phải có bằng chứng phù hợp: test, runtime, CI hoặc review theo gate. | Q31: XONG phải có bằng chứng phù hợp: test, runtime, CI hoặc review theo gate. | R31: XONG phải có bằng chứng phù hợp: test, runtime, CI hoặc review theo gate.
B32: 3 | C32: Phase 2 chưa được bắt đầu chính thức. | D32: Phase 2 chưa được bắt đầu chính thức. | E32: Phase 2 chưa được bắt đầu chính thức. | F32: Phase 2 chưa được bắt đầu chính thức. | G32: Phase 2 chưa được bắt đầu chính thức. | H32: Phase 2 chưa được bắt đầu chính thức. | I32: Chỉ đủ điều kiện khi toàn bộ task bắt buộc của Phase 1 XONG. | J32: Chỉ đủ điều kiện khi toàn bộ task bắt buộc của Phase 1 XONG. | K32: Chỉ đủ điều kiện khi toàn bộ task bắt buộc của Phase 1 XONG. | L32: Chỉ đủ điều kiện khi toàn bộ task bắt buộc của Phase 1 XONG. | M32: Chỉ đủ điều kiện khi toàn bộ task bắt buộc của Phase 1 XONG. | N32: Chỉ đủ điều kiện khi toàn bộ task bắt buộc của Phase 1 XONG. | O32: Chỉ đủ điều kiện khi toàn bộ task bắt buộc của Phase 1 XONG. | P32: Chỉ đủ điều kiện khi toàn bộ task bắt buộc của Phase 1 XONG. | Q32: Chỉ đủ điều kiện khi toàn bộ task bắt buộc của Phase 1 XONG. | R32: Chỉ đủ điều kiện khi toàn bộ task bắt buộc của Phase 1 XONG.
B33: 3 | C33: Phase 2 chưa được bắt đầu chính thức. | D33: Phase 2 chưa được bắt đầu chính thức. | E33: Phase 2 chưa được bắt đầu chính thức. | F33: Phase 2 chưa được bắt đầu chính thức. | G33: Phase 2 chưa được bắt đầu chính thức. | H33: Phase 2 chưa được bắt đầu chính thức. | I33: Chỉ đủ điều kiện khi toàn bộ task bắt buộc của Phase 1 XONG. | J33: Chỉ đủ điều kiện khi toàn bộ task bắt buộc của Phase 1 XONG. | K33: Chỉ đủ điều kiện khi toàn bộ task bắt buộc của Phase 1 XONG. | L33: Chỉ đủ điều kiện khi toàn bộ task bắt buộc của Phase 1 XONG. | M33: Chỉ đủ điều kiện khi toàn bộ task bắt buộc của Phase 1 XONG. | N33: Chỉ đủ điều kiện khi toàn bộ task bắt buộc của Phase 1 XONG. | O33: Chỉ đủ điều kiện khi toàn bộ task bắt buộc của Phase 1 XONG. | P33: Chỉ đủ điều kiện khi toàn bộ task bắt buộc của Phase 1 XONG. | Q33: Chỉ đủ điều kiện khi toàn bộ task bắt buộc của Phase 1 XONG. | R33: Chỉ đủ điều kiện khi toàn bộ task bắt buộc của Phase 1 XONG.
B34: 4 | C34: Task là nguồn trạng thái hằng ngày. | D34: Task là nguồn trạng thái hằng ngày. | E34: Task là nguồn trạng thái hằng ngày. | F34: Task là nguồn trạng thái hằng ngày. | G34: Task là nguồn trạng thái hằng ngày. | H34: Task là nguồn trạng thái hằng ngày. | I34: Tổng quan và checklist Phase 1 tự đọc trạng thái từ 04_CONG_VIEC để tránh cập nhật lệch. | J34: Tổng quan và checklist Phase 1 tự đọc trạng thái từ 04_CONG_VIEC để tránh cập nhật lệch. | K34: Tổng quan và checklist Phase 1 tự đọc trạng thái từ 04_CONG_VIEC để tránh cập nhật lệch. | L34: Tổng quan và checklist Phase 1 tự đọc trạng thái từ 04_CONG_VIEC để tránh cập nhật lệch. | M34: Tổng quan và checklist Phase 1 tự đọc trạng thái từ 04_CONG_VIEC để tránh cập nhật lệch. | N34: Tổng quan và checklist Phase 1 tự đọc trạng thái từ 04_CONG_VIEC để tránh cập nhật lệch. | O34: Tổng quan và checklist Phase 1 tự đọc trạng thái từ 04_CONG_VIEC để tránh cập nhật lệch. | P34: Tổng quan và checklist Phase 1 tự đọc trạng thái từ 04_CONG_VIEC để tránh cập nhật lệch. | Q34: Tổng quan và checklist Phase 1 tự đọc trạng thái từ 04_CONG_VIEC để tránh cập nhật lệch. | R34: Tổng quan và checklist Phase 1 tự đọc trạng thái từ 04_CONG_VIEC để tránh cập nhật lệch.
B35: 4 | C35: Task là nguồn trạng thái hằng ngày. | D35: Task là nguồn trạng thái hằng ngày. | E35: Task là nguồn trạng thái hằng ngày. | F35: Task là nguồn trạng thái hằng ngày. | G35: Task là nguồn trạng thái hằng ngày. | H35: Task là nguồn trạng thái hằng ngày. | I35: Tổng quan và checklist Phase 1 tự đọc trạng thái từ 04_CONG_VIEC để tránh cập nhật lệch. | J35: Tổng quan và checklist Phase 1 tự đọc trạng thái từ 04_CONG_VIEC để tránh cập nhật lệch. | K35: Tổng quan và checklist Phase 1 tự đọc trạng thái từ 04_CONG_VIEC để tránh cập nhật lệch. | L35: Tổng quan và checklist Phase 1 tự đọc trạng thái từ 04_CONG_VIEC để tránh cập nhật lệch. | M35: Tổng quan và checklist Phase 1 tự đọc trạng thái từ 04_CONG_VIEC để tránh cập nhật lệch. | N35: Tổng quan và checklist Phase 1 tự đọc trạng thái từ 04_CONG_VIEC để tránh cập nhật lệch. | O35: Tổng quan và checklist Phase 1 tự đọc trạng thái từ 04_CONG_VIEC để tránh cập nhật lệch. | P35: Tổng quan và checklist Phase 1 tự đọc trạng thái từ 04_CONG_VIEC để tránh cập nhật lệch. | Q35: Tổng quan và checklist Phase 1 tự đọc trạng thái từ 04_CONG_VIEC để tránh cập nhật lệch. | R35: Tổng quan và checklist Phase 1 tự đọc trạng thái từ 04_CONG_VIEC để tránh cập nhật lệch.
B36: 5 | C36: Không ghi mật khẩu/token vào file. | D36: Không ghi mật khẩu/token vào file. | E36: Không ghi mật khẩu/token vào file. | F36: Không ghi mật khẩu/token vào file. | G36: Không ghi mật khẩu/token vào file. | H36: Không ghi mật khẩu/token vào file. | I36: Chỉ ghi tên biến môi trường hoặc nơi lưu secret; tuyệt đối không ghi plaintext credential. | J36: Chỉ ghi tên biến môi trường hoặc nơi lưu secret; tuyệt đối không ghi plaintext credential. | K36: Chỉ ghi tên biến môi trường hoặc nơi lưu secret; tuyệt đối không ghi plaintext credential. | L36: Chỉ ghi tên biến môi trường hoặc nơi lưu secret; tuyệt đối không ghi plaintext credential. | M36: Chỉ ghi tên biến môi trường hoặc nơi lưu secret; tuyệt đối không ghi plaintext credential. | N36: Chỉ ghi tên biến môi trường hoặc nơi lưu secret; tuyệt đối không ghi plaintext credential. | O36: Chỉ ghi tên biến môi trường hoặc nơi lưu secret; tuyệt đối không ghi plaintext credential. | P36: Chỉ ghi tên biến môi trường hoặc nơi lưu secret; tuyệt đối không ghi plaintext credential. | Q36: Chỉ ghi tên biến môi trường hoặc nơi lưu secret; tuyệt đối không ghi plaintext credential. | R36: Chỉ ghi tên biến môi trường hoặc nơi lưu secret; tuyệt đối không ghi plaintext credential.
B37: 5 | C37: Không ghi mật khẩu/token vào file. | D37: Không ghi mật khẩu/token vào file. | E37: Không ghi mật khẩu/token vào file. | F37: Không ghi mật khẩu/token vào file. | G37: Không ghi mật khẩu/token vào file. | H37: Không ghi mật khẩu/token vào file. | I37: Chỉ ghi tên biến môi trường hoặc nơi lưu secret; tuyệt đối không ghi plaintext credential. | J37: Chỉ ghi tên biến môi trường hoặc nơi lưu secret; tuyệt đối không ghi plaintext credential. | K37: Chỉ ghi tên biến môi trường hoặc nơi lưu secret; tuyệt đối không ghi plaintext credential. | L37: Chỉ ghi tên biến môi trường hoặc nơi lưu secret; tuyệt đối không ghi plaintext credential. | M37: Chỉ ghi tên biến môi trường hoặc nơi lưu secret; tuyệt đối không ghi plaintext credential. | N37: Chỉ ghi tên biến môi trường hoặc nơi lưu secret; tuyệt đối không ghi plaintext credential. | O37: Chỉ ghi tên biến môi trường hoặc nơi lưu secret; tuyệt đối không ghi plaintext credential. | P37: Chỉ ghi tên biến môi trường hoặc nơi lưu secret; tuyệt đối không ghi plaintext credential. | Q37: Chỉ ghi tên biến môi trường hoặc nơi lưu secret; tuyệt đối không ghi plaintext credential. | R37: Chỉ ghi tên biến môi trường hoặc nơi lưu secret; tuyệt đối không ghi plaintext credential.
B40: Hướng dẫn chọn sheet | C40: Hướng dẫn chọn sheet | D40: Hướng dẫn chọn sheet | E40: Hướng dẫn chọn sheet | F40: Hướng dẫn chọn sheet | G40: Hướng dẫn chọn sheet | H40: Hướng dẫn chọn sheet | I40: Hướng dẫn chọn sheet | J40: Hướng dẫn chọn sheet | K40: Hướng dẫn chọn sheet | L40: Hướng dẫn chọn sheet | M40: Hướng dẫn chọn sheet | N40: Hướng dẫn chọn sheet | O40: Hướng dẫn chọn sheet | P40: Hướng dẫn chọn sheet | Q40: Hướng dẫn chọn sheet | R40: Hướng dẫn chọn sheet
B41: Hướng dẫn chọn sheet | C41: Hướng dẫn chọn sheet | D41: Hướng dẫn chọn sheet | E41: Hướng dẫn chọn sheet | F41: Hướng dẫn chọn sheet | G41: Hướng dẫn chọn sheet | H41: Hướng dẫn chọn sheet | I41: Hướng dẫn chọn sheet | J41: Hướng dẫn chọn sheet | K41: Hướng dẫn chọn sheet | L41: Hướng dẫn chọn sheet | M41: Hướng dẫn chọn sheet | N41: Hướng dẫn chọn sheet | O41: Hướng dẫn chọn sheet | P41: Hướng dẫn chọn sheet | Q41: Hướng dẫn chọn sheet | R41: Hướng dẫn chọn sheet
B43: Dự án đang ở đâu? | C43: Dự án đang ở đâu? | D43: Dự án đang ở đâu? | E43: Dự án đang ở đâu? | F43: Dự án đang ở đâu? | G43: Dự án đang ở đâu? | H43: =HYPERLINK("#'01_TONG_QUAN'!A1","01_TONG_QUAN") -> 01_TONG_QUAN | M43: Xem phase hiện tại, blocker, tiến độ Phase 1 và thứ tự việc tiếp theo. | N43: Xem phase hiện tại, blocker, tiến độ Phase 1 và thứ tự việc tiếp theo. | O43: Xem phase hiện tại, blocker, tiến độ Phase 1 và thứ tự việc tiếp theo. | P43: Xem phase hiện tại, blocker, tiến độ Phase 1 và thứ tự việc tiếp theo. | Q43: Xem phase hiện tại, blocker, tiến độ Phase 1 và thứ tự việc tiếp theo. | R43: Xem phase hiện tại, blocker, tiến độ Phase 1 và thứ tự việc tiếp theo.
B44: Dự án đang ở đâu? | C44: Dự án đang ở đâu? | D44: Dự án đang ở đâu? | E44: Dự án đang ở đâu? | F44: Dự án đang ở đâu? | G44: Dự án đang ở đâu? | M44: Xem phase hiện tại, blocker, tiến độ Phase 1 và thứ tự việc tiếp theo. | N44: Xem phase hiện tại, blocker, tiến độ Phase 1 và thứ tự việc tiếp theo. | O44: Xem phase hiện tại, blocker, tiến độ Phase 1 và thứ tự việc tiếp theo. | P44: Xem phase hiện tại, blocker, tiến độ Phase 1 và thứ tự việc tiếp theo. | Q44: Xem phase hiện tại, blocker, tiến độ Phase 1 và thứ tự việc tiếp theo. | R44: Xem phase hiện tại, blocker, tiến độ Phase 1 và thứ tự việc tiếp theo.
B45: Dự án đang ở đâu? | C45: Dự án đang ở đâu? | D45: Dự án đang ở đâu? | E45: Dự án đang ở đâu? | F45: Dự án đang ở đâu? | G45: Dự án đang ở đâu? | M45: Xem phase hiện tại, blocker, tiến độ Phase 1 và thứ tự việc tiếp theo. | N45: Xem phase hiện tại, blocker, tiến độ Phase 1 và thứ tự việc tiếp theo. | O45: Xem phase hiện tại, blocker, tiến độ Phase 1 và thứ tự việc tiếp theo. | P45: Xem phase hiện tại, blocker, tiến độ Phase 1 và thứ tự việc tiếp theo. | Q45: Xem phase hiện tại, blocker, tiến độ Phase 1 và thứ tự việc tiếp theo. | R45: Xem phase hiện tại, blocker, tiến độ Phase 1 và thứ tự việc tiếp theo.
B46: Mingo là sản phẩm gì, nghiệp vụ ra sao? | C46: Mingo là sản phẩm gì, nghiệp vụ ra sao? | D46: Mingo là sản phẩm gì, nghiệp vụ ra sao? | E46: Mingo là sản phẩm gì, nghiệp vụ ra sao? | F46: Mingo là sản phẩm gì, nghiệp vụ ra sao? | G46: Mingo là sản phẩm gì, nghiệp vụ ra sao? | H46: =HYPERLINK("#'02_SAN_PHAM'!A1","02_SAN_PHAM") -> 02_SAN_PHAM | M46: Hiểu luồng learner, luật dễ làm sai, nội dung đã chốt/chưa chốt, V3.2. | N46: Hiểu luồng learner, luật dễ làm sai, nội dung đã chốt/chưa chốt, V3.2. | O46: Hiểu luồng learner, luật dễ làm sai, nội dung đã chốt/chưa chốt, V3.2. | P46: Hiểu luồng learner, luật dễ làm sai, nội dung đã chốt/chưa chốt, V3.2. | Q46: Hiểu luồng learner, luật dễ làm sai, nội dung đã chốt/chưa chốt, V3.2. | R46: Hiểu luồng learner, luật dễ làm sai, nội dung đã chốt/chưa chốt, V3.2.
B47: Mingo là sản phẩm gì, nghiệp vụ ra sao? | C47: Mingo là sản phẩm gì, nghiệp vụ ra sao? | D47: Mingo là sản phẩm gì, nghiệp vụ ra sao? | E47: Mingo là sản phẩm gì, nghiệp vụ ra sao? | F47: Mingo là sản phẩm gì, nghiệp vụ ra sao? | G47: Mingo là sản phẩm gì, nghiệp vụ ra sao? | M47: Hiểu luồng learner, luật dễ làm sai, nội dung đã chốt/chưa chốt, V3.2. | N47: Hiểu luồng learner, luật dễ làm sai, nội dung đã chốt/chưa chốt, V3.2. | O47: Hiểu luồng learner, luật dễ làm sai, nội dung đã chốt/chưa chốt, V3.2. | P47: Hiểu luồng learner, luật dễ làm sai, nội dung đã chốt/chưa chốt, V3.2. | Q47: Hiểu luồng learner, luật dễ làm sai, nội dung đã chốt/chưa chốt, V3.2. | R47: Hiểu luồng learner, luật dễ làm sai, nội dung đã chốt/chưa chốt, V3.2.
B48: Mingo là sản phẩm gì, nghiệp vụ ra sao? | C48: Mingo là sản phẩm gì, nghiệp vụ ra sao? | D48: Mingo là sản phẩm gì, nghiệp vụ ra sao? | E48: Mingo là sản phẩm gì, nghiệp vụ ra sao? | F48: Mingo là sản phẩm gì, nghiệp vụ ra sao? | G48: Mingo là sản phẩm gì, nghiệp vụ ra sao? | M48: Hiểu luồng learner, luật dễ làm sai, nội dung đã chốt/chưa chốt, V3.2. | N48: Hiểu luồng learner, luật dễ làm sai, nội dung đã chốt/chưa chốt, V3.2. | O48: Hiểu luồng learner, luật dễ làm sai, nội dung đã chốt/chưa chốt, V3.2. | P48: Hiểu luồng learner, luật dễ làm sai, nội dung đã chốt/chưa chốt, V3.2. | Q48: Hiểu luồng learner, luật dễ làm sai, nội dung đã chốt/chưa chốt, V3.2. | R48: Hiểu luồng learner, luật dễ làm sai, nội dung đã chốt/chưa chốt, V3.2.
B49: Toàn bộ Phase 0 → 17 là gì? | C49: Toàn bộ Phase 0 → 17 là gì? | D49: Toàn bộ Phase 0 → 17 là gì? | E49: Toàn bộ Phase 0 → 17 là gì? | F49: Toàn bộ Phase 0 → 17 là gì? | G49: Toàn bộ Phase 0 → 17 là gì? | H49: =HYPERLINK("#'03_ROADMAP'!A1","03_ROADMAP") -> 03_ROADMAP | M49: Xem mục tiêu từng phase và checklist Phase 1 được đồng bộ từ Task. | N49: Xem mục tiêu từng phase và checklist Phase 1 được đồng bộ từ Task. | O49: Xem mục tiêu từng phase và checklist Phase 1 được đồng bộ từ Task. | P49: Xem mục tiêu từng phase và checklist Phase 1 được đồng bộ từ Task. | Q49: Xem mục tiêu từng phase và checklist Phase 1 được đồng bộ từ Task. | R49: Xem mục tiêu từng phase và checklist Phase 1 được đồng bộ từ Task.
B50: Toàn bộ Phase 0 → 17 là gì? | C50: Toàn bộ Phase 0 → 17 là gì? | D50: Toàn bộ Phase 0 → 17 là gì? | E50: Toàn bộ Phase 0 → 17 là gì? | F50: Toàn bộ Phase 0 → 17 là gì? | G50: Toàn bộ Phase 0 → 17 là gì? | M50: Xem mục tiêu từng phase và checklist Phase 1 được đồng bộ từ Task. | N50: Xem mục tiêu từng phase và checklist Phase 1 được đồng bộ từ Task. | O50: Xem mục tiêu từng phase và checklist Phase 1 được đồng bộ từ Task. | P50: Xem mục tiêu từng phase và checklist Phase 1 được đồng bộ từ Task. | Q50: Xem mục tiêu từng phase và checklist Phase 1 được đồng bộ từ Task. | R50: Xem mục tiêu từng phase và checklist Phase 1 được đồng bộ từ Task.
B51: Toàn bộ Phase 0 → 17 là gì? | C51: Toàn bộ Phase 0 → 17 là gì? | D51: Toàn bộ Phase 0 → 17 là gì? | E51: Toàn bộ Phase 0 → 17 là gì? | F51: Toàn bộ Phase 0 → 17 là gì? | G51: Toàn bộ Phase 0 → 17 là gì? | M51: Xem mục tiêu từng phase và checklist Phase 1 được đồng bộ từ Task. | N51: Xem mục tiêu từng phase và checklist Phase 1 được đồng bộ từ Task. | O51: Xem mục tiêu từng phase và checklist Phase 1 được đồng bộ từ Task. | P51: Xem mục tiêu từng phase và checklist Phase 1 được đồng bộ từ Task. | Q51: Xem mục tiêu từng phase và checklist Phase 1 được đồng bộ từ Task. | R51: Xem mục tiêu từng phase và checklist Phase 1 được đồng bộ từ Task.
...

Sheet 01_TONG_QUAN
B2: Tổng quan dự án MINGO | C2: Tổng quan dự án MINGO | D2: Tổng quan dự án MINGO | E2: Tổng quan dự án MINGO | F2: Tổng quan dự án MINGO | G2: Tổng quan dự án MINGO | H2: Tổng quan dự án MINGO | I2: Tổng quan dự án MINGO | J2: Tổng quan dự án MINGO | K2: Tổng quan dự án MINGO | L2: Tổng quan dự án MINGO | M2: Tổng quan dự án MINGO | N2: Tổng quan dự án MINGO | O2: Tổng quan dự án MINGO | P2: Tổng quan dự án MINGO | Q2: Tổng quan dự án MINGO | R2: Tổng quan dự án MINGO
B3: Tổng quan dự án MINGO | C3: Tổng quan dự án MINGO | D3: Tổng quan dự án MINGO | E3: Tổng quan dự án MINGO | F3: Tổng quan dự án MINGO | G3: Tổng quan dự án MINGO | H3: Tổng quan dự án MINGO | I3: Tổng quan dự án MINGO | J3: Tổng quan dự án MINGO | K3: Tổng quan dự án MINGO | L3: Tổng quan dự án MINGO | M3: Tổng quan dự án MINGO | N3: Tổng quan dự án MINGO | O3: Tổng quan dự án MINGO | P3: Tổng quan dự án MINGO | Q3: Tổng quan dự án MINGO | R3: Tổng quan dự án MINGO
B4: Mingo — Adaptive Language Learning & Early Intervention Platform | C4: Mingo — Adaptive Language Learning & Early Intervention Platform | D4: Mingo — Adaptive Language Learning & Early Intervention Platform | E4: Mingo — Adaptive Language Learning & Early Intervention Platform | F4: Mingo — Adaptive Language Learning & Early Intervention Platform | G4: Mingo — Adaptive Language Learning & Early Intervention Platform | H4: Mingo — Adaptive Language Learning & Early Intervention Platform | I4: Mingo — Adaptive Language Learning & Early Intervention Platform | J4: Mingo — Adaptive Language Learning & Early Intervention Platform | K4: Mingo — Adaptive Language Learning & Early Intervention Platform | L4: Mingo — Adaptive Language Learning & Early Intervention Platform | M4: Mingo — Adaptive Language Learning & Early Intervention Platform | N4: Mingo — Adaptive Language Learning & Early Intervention Platform | O4: Mingo — Adaptive Language Learning & Early Intervention Platform | P4: Mingo — Adaptive Language Learning & Early Intervention Platform | Q4: Mingo — Adaptive Language Learning & Early Intervention Platform | R4: Mingo — Adaptive Language Learning & Early Intervention Platform
B6: PHASE HIỆN TẠI | C6: PHASE HIỆN TẠI | D6: PHASE HIỆN TẠI | E6: PHASE HIỆN TẠI | G6: TASK PHASE 1 ĐÃ XONG | H6: TASK PHASE 1 ĐÃ XONG | I6: TASK PHASE 1 ĐÃ XONG | J6: TASK PHASE 1 ĐÃ XONG | L6: NHÓM BỊ CHẶN | M6: NHÓM BỊ CHẶN | N6: NHÓM BỊ CHẶN | P6: TASK ĐANG LÀM | Q6: TASK ĐANG LÀM | R6: TASK ĐANG LÀM
B7: Phase 1 | C7: Phase 1 | D7: Phase 1 | E7: Phase 1 | G7: =COUNTIFS('04_CONG_VIEC'!$B$5:$B$200,"P1",'04_CONG_VIEC'!$F$5:$F$200,"XONG")/COUNTIF('04_CONG_VIEC'!$B$5:$B$200,"P1") -> 0 | L7: =COUNTIFS(E20:E25,"BỊ CHẶN") -> 5 | P7: =COUNTIFS('04_CONG_VIEC'!$F$5:$F$200,"ĐANG LÀM") -> 1
B8: Phase 1 | C8: Phase 1 | D8: Phase 1 | E8: Phase 1
B9: Nền tảng triển khai | C9: Nền tảng triển khai | D9: Nền tảng triển khai | E9: Nền tảng triển khai | G9: Tiến độ theo trạng thái task | H9: Tiến độ theo trạng thái task | I9: Tiến độ theo trạng thái task | J9: Tiến độ theo trạng thái task | L9: Đọc từ nhóm blocker | M9: Đọc từ nhóm blocker | N9: Đọc từ nhóm blocker | P9: Toàn bộ công việc | Q9: Toàn bộ công việc | R9: Toàn bộ công việc
B10: Nền tảng triển khai | C10: Nền tảng triển khai | D10: Nền tảng triển khai | E10: Nền tảng triển khai | G10: Tiến độ theo trạng thái task | H10: Tiến độ theo trạng thái task | I10: Tiến độ theo trạng thái task | J10: Tiến độ theo trạng thái task | L10: Đọc từ nhóm blocker | M10: Đọc từ nhóm blocker | N10: Đọc từ nhóm blocker | P10: Toàn bộ công việc | Q10: Toàn bộ công việc | R10: Toàn bộ công việc
B12: Mục tiêu chính | C12: Mục tiêu chính | D12: Mục tiêu chính | E12: Mục tiêu chính | F12: Mục tiêu chính | G12: Mục tiêu chính | H12: Mục tiêu chính | I12: Mục tiêu chính | K12: Phase 1 — Nền tảng triển khai (Implementation Foundation) | L12: Phase 1 — Nền tảng triển khai (Implementation Foundation) | M12: Phase 1 — Nền tảng triển khai (Implementation Foundation) | N12: Phase 1 — Nền tảng triển khai (Implementation Foundation) | O12: Phase 1 — Nền tảng triển khai (Implementation Foundation) | P12: Phase 1 — Nền tảng triển khai (Implementation Foundation) | Q12: Phase 1 — Nền tảng triển khai (Implementation Foundation) | R12: Phase 1 — Nền tảng triển khai (Implementation Foundation)
B13: Xây sản phẩm học ngôn ngữ hoàn chỉnh: học tập → offline → dữ liệu → intelligence → risk → recommendation → staff → production. | C13: Xây sản phẩm học ngôn ngữ hoàn chỉnh: học tập → offline → dữ liệu → intelligence → risk → recommendation → staff → production. | D13: Xây sản phẩm học ngôn ngữ hoàn chỉnh: học tập → offline → dữ liệu → intelligence → risk → recommendation → staff → production. | E13: Xây sản phẩm học ngôn ngữ hoàn chỉnh: học tập → offline → dữ liệu → intelligence → risk → recommendation → staff → production. | F13: Xây sản phẩm học ngôn ngữ hoàn chỉnh: học tập → offline → dữ liệu → intelligence → risk → recommendation → staff → production. | G13: Xây sản phẩm học ngôn ngữ hoàn chỉnh: học tập → offline → dữ liệu → intelligence → risk → recommendation → staff → production. | H13: Xây sản phẩm học ngôn ngữ hoàn chỉnh: học tập → offline → dữ liệu → intelligence → risk → recommendation → staff → production. | I13: Xây sản phẩm học ngôn ngữ hoàn chỉnh: học tập → offline → dữ liệu → intelligence → risk → recommendation → staff → production. | K13: Trạng thái | L13: Trạng thái | M13: Trạng thái | N13: =IF(COUNTIFS('04_CONG_VIEC'!$B$5:$B$200,"P1",'04_CONG_VIEC'!$F$5:$F$200,"<>XONG")=0,"XONG","ĐANG LÀM") -> ĐANG LÀM
B14: Xây sản phẩm học ngôn ngữ hoàn chỉnh: học tập → offline → dữ liệu → intelligence → risk → recommendation → staff → production. | C14: Xây sản phẩm học ngôn ngữ hoàn chỉnh: học tập → offline → dữ liệu → intelligence → risk → recommendation → staff → production. | D14: Xây sản phẩm học ngôn ngữ hoàn chỉnh: học tập → offline → dữ liệu → intelligence → risk → recommendation → staff → production. | E14: Xây sản phẩm học ngôn ngữ hoàn chỉnh: học tập → offline → dữ liệu → intelligence → risk → recommendation → staff → production. | F14: Xây sản phẩm học ngôn ngữ hoàn chỉnh: học tập → offline → dữ liệu → intelligence → risk → recommendation → staff → production. | G14: Xây sản phẩm học ngôn ngữ hoàn chỉnh: học tập → offline → dữ liệu → intelligence → risk → recommendation → staff → production. | H14: Xây sản phẩm học ngôn ngữ hoàn chỉnh: học tập → offline → dữ liệu → intelligence → risk → recommendation → staff → production. | I14: Xây sản phẩm học ngôn ngữ hoàn chỉnh: học tập → offline → dữ liệu → intelligence → risk → recommendation → staff → production. | K14: Gate Phase 1 | L14: Gate Phase 1 | M14: Gate Phase 1 | N14: =IF(COUNTIFS('04_CONG_VIEC'!$B$5:$B$200,"P1",'04_CONG_VIEC'!$F$5:$F$200,"<>XONG")=0,"ĐÃ PASS","CHƯA PASS") -> CHƯA PASS
B15: Xây sản phẩm học ngôn ngữ hoàn chỉnh: học tập → offline → dữ liệu → intelligence → risk → recommendation → staff → production. | C15: Xây sản phẩm học ngôn ngữ hoàn chỉnh: học tập → offline → dữ liệu → intelligence → risk → recommendation → staff → production. | D15: Xây sản phẩm học ngôn ngữ hoàn chỉnh: học tập → offline → dữ liệu → intelligence → risk → recommendation → staff → production. | E15: Xây sản phẩm học ngôn ngữ hoàn chỉnh: học tập → offline → dữ liệu → intelligence → risk → recommendation → staff → production. | F15: Xây sản phẩm học ngôn ngữ hoàn chỉnh: học tập → offline → dữ liệu → intelligence → risk → recommendation → staff → production. | G15: Xây sản phẩm học ngôn ngữ hoàn chỉnh: học tập → offline → dữ liệu → intelligence → risk → recommendation → staff → production. | H15: Xây sản phẩm học ngôn ngữ hoàn chỉnh: học tập → offline → dữ liệu → intelligence → risk → recommendation → staff → production. | I15: Xây sản phẩm học ngôn ngữ hoàn chỉnh: học tập → offline → dữ liệu → intelligence → risk → recommendation → staff → production. | K15: Phase 2 | L15: Phase 2 | M15: Phase 2 | N15: =IF(N14="ĐÃ PASS","ĐỦ ĐIỀU KIỆN LẬP PHASE 2","CHƯA ĐƯỢC BẮT ĐẦU CHÍNH THỨC") -> CHƯA ĐƯỢC BẮT ĐẦU CHÍNH THỨC
B16: Xây sản phẩm học ngôn ngữ hoàn chỉnh: học tập → offline → dữ liệu → intelligence → risk → recommendation → staff → production. | C16: Xây sản phẩm học ngôn ngữ hoàn chỉnh: học tập → offline → dữ liệu → intelligence → risk → recommendation → staff → production. | D16: Xây sản phẩm học ngôn ngữ hoàn chỉnh: học tập → offline → dữ liệu → intelligence → risk → recommendation → staff → production. | E16: Xây sản phẩm học ngôn ngữ hoàn chỉnh: học tập → offline → dữ liệu → intelligence → risk → recommendation → staff → production. | F16: Xây sản phẩm học ngôn ngữ hoàn chỉnh: học tập → offline → dữ liệu → intelligence → risk → recommendation → staff → production. | G16: Xây sản phẩm học ngôn ngữ hoàn chỉnh: học tập → offline → dữ liệu → intelligence → risk → recommendation → staff → production. | H16: Xây sản phẩm học ngôn ngữ hoàn chỉnh: học tập → offline → dữ liệu → intelligence → risk → recommendation → staff → production. | I16: Xây sản phẩm học ngôn ngữ hoàn chỉnh: học tập → offline → dữ liệu → intelligence → risk → recommendation → staff → production. | K16: Phase 0 | L16: Phase 0 | M16: Phase 0 | N16: XONG — V3.2.0 là baseline chuẩn của Phase 0 | O16: XONG — V3.2.0 là baseline chuẩn của Phase 0 | P16: XONG — V3.2.0 là baseline chuẩn của Phase 0 | Q16: XONG — V3.2.0 là baseline chuẩn của Phase 0 | R16: XONG — V3.2.0 là baseline chuẩn của Phase 0
B18: CÁC BLOCKER CHÍNH — TỰ ĐỒNG ĐỌC TỪ TASK | C18: CÁC BLOCKER CHÍNH — TỰ ĐỒNG ĐỌC TỪ TASK | D18: CÁC BLOCKER CHÍNH — TỰ ĐỒNG ĐỌC TỪ TASK | E18: CÁC BLOCKER CHÍNH — TỰ ĐỒNG ĐỌC TỪ TASK | F18: CÁC BLOCKER CHÍNH — TỰ ĐỒNG ĐỌC TỪ TASK | G18: CÁC BLOCKER CHÍNH — TỰ ĐỒNG ĐỌC TỪ TASK | H18: CÁC BLOCKER CHÍNH — TỰ ĐỒNG ĐỌC TỪ TASK | I18: CÁC BLOCKER CHÍNH — TỰ ĐỒNG ĐỌC TỪ TASK | J18: CÁC BLOCKER CHÍNH — TỰ ĐỒNG ĐỌC TỪ TASK | K18: CÁC BLOCKER CHÍNH — TỰ ĐỒNG ĐỌC TỪ TASK | L18: CÁC BLOCKER CHÍNH — TỰ ĐỒNG ĐỌC TỪ TASK | M18: CÁC BLOCKER CHÍNH — TỰ ĐỒNG ĐỌC TỪ TASK | N18: CÁC BLOCKER CHÍNH — TỰ ĐỒNG ĐỌC TỪ TASK | O18: CÁC BLOCKER CHÍNH — TỰ ĐỒNG ĐỌC TỪ TASK | P18: CÁC BLOCKER CHÍNH — TỰ ĐỒNG ĐỌC TỪ TASK | Q18: CÁC BLOCKER CHÍNH — TỰ ĐỒNG ĐỌC TỪ TASK | R18: CÁC BLOCKER CHÍNH — TỰ ĐỒNG ĐỌC TỪ TASK
B19: Nhóm | C19: Nhóm | D19: Nhóm | E19: Trạng thái | F19: Trạng thái | G19: Trạng thái | H19: Việc tiếp theo | I19: Việc tiếp theo | J19: Việc tiếp theo | K19: Việc tiếp theo | L19: Việc tiếp theo | M19: Việc tiếp theo | N19: Việc tiếp theo | O19: Task nguồn | P19: Task nguồn | Q19: Task nguồn | R19: Task nguồn
B20: V3.2 original | C20: V3.2 original | D20: V3.2 original | E20: =IF(AND(VLOOKUP("P1-T001",'04_CONG_VIEC'!$A$5:$F$200,6,FALSE)="XONG",VLOOKUP("P1-T002",'04_CONG_VIEC'!$A$5:$F$200,6,FALSE)="XONG",VLOOKUP("P1-T003",'04_CONG_VIEC'!$A$5:$F$200,6,FALSE)="XONG"),"XONG",IF(OR(VLOOKUP("P1-T001",'04_CONG_VIEC'!$A$5:$F$200,6,FALSE)="BỊ CHẶN",VLOOKUP("P1-T002",'04_CONG_VIEC'!$A$5:$F$200,6,FALSE)="BỊ CHẶN",VLOOKUP("P1-T003",'04_CONG_VIEC'!$A$5:$F$200,6,FALSE)="BỊ CHẶN"),"BỊ CHẶN","ĐANG LÀM")) -> ĐANG LÀM | H20: Import exact package + rerun 115 contract + 22 SQL. | I20: Import exact package + rerun 115 contract + 22 SQL. | J20: Import exact package + rerun 115 contract + 22 SQL. | K20: Import exact package + rerun 115 contract + 22 SQL. | L20: Import exact package + rerun 115 contract + 22 SQL. | M20: Import exact package + rerun 115 contract + 22 SQL. | N20: Import exact package + rerun 115 contract + 22 SQL. | O20: P1-T001..T003 | P20: P1-T001..T003 | Q20: P1-T001..T003 | R20: P1-T001..T003
B21: PostgreSQL | C21: PostgreSQL | D21: PostgreSQL | E21: =IF(AND(VLOOKUP("P1-T005",'04_CONG_VIEC'!$A$5:$F$200,6,FALSE)="XONG",VLOOKUP("P1-T006",'04_CONG_VIEC'!$A$5:$F$200,6,FALSE)="XONG"),"XONG",IF(OR(VLOOKUP("P1-T005",'04_CONG_VIEC'!$A$5:$F$200,6,FALSE)="BỊ CHẶN",VLOOKUP("P1-T006",'04_CONG_VIEC'!$A$5:$F$200,6,FALSE)="BỊ CHẶN"),"BỊ CHẶN","CHỜ")) -> BỊ CHẶN | H21: Provision/access DB → migration → 6 DB tests. | I21: Provision/access DB → migration → 6 DB tests. | J21: Provision/access DB → migration → 6 DB tests. | K21: Provision/access DB → migration → 6 DB tests. | L21: Provision/access DB → migration → 6 DB tests. | M21: Provision/access DB → migration → 6 DB tests. | N21: Provision/access DB → migration → 6 DB tests. | O21: P1-T005..T006 | P21: P1-T005..T006 | Q21: P1-T005..T006 | R21: P1-T005..T006
B22: API + Worker | C22: API + Worker | D22: API + Worker | E22: =VLOOKUP("P1-T007",'04_CONG_VIEC'!$A$5:$F$200,6,FALSE) -> BỊ CHẶN | H22: DB khỏe → /ready=200 → worker probe PASS. | I22: DB khỏe → /ready=200 → worker probe PASS. | J22: DB khỏe → /ready=200 → worker probe PASS. | K22: DB khỏe → /ready=200 → worker probe PASS. | L22: DB khỏe → /ready=200 → worker probe PASS. | M22: DB khỏe → /ready=200 → worker probe PASS. | N22: DB khỏe → /ready=200 → worker probe PASS. | O22: P1-T007 | P22: P1-T007 | Q22: P1-T007 | R22: P1-T007
B23: Flutter learner/staff | C23: Flutter learner/staff | D23: Flutter learner/staff | E23: =IF(AND(VLOOKUP("P1-T009",'04_CONG_VIEC'!$A$5:$F$200,6,FALSE)="XONG",VLOOKUP("P1-T010",'04_CONG_VIEC'!$A$5:$F$200,6,FALSE)="XONG"),"XONG",IF(OR(VLOOKUP("P1-T008",'04_CONG_VIEC'!$A$5:$F$200,6,FALSE)="BỊ CHẶN",VLOOKUP("P1-T009",'04_CONG_VIEC'!$A$5:$F$200,6,FALSE)="BỊ CHẶN",VLOOKUP("P1-T010",'04_CONG_VIEC'!$A$5:$F$200,6,FALSE)="BỊ CHẶN"),"BỊ CHẶN","CHỜ")) -> BỊ CHẶN | H23: Toolchain → learner Android boot + staff Web boot. | I23: Toolchain → learner Android boot + staff Web boot. | J23: Toolchain → learner Android boot + staff Web boot. | K23: Toolchain → learner Android boot + staff Web boot. | L23: Toolchain → learner Android boot + staff Web boot. | M23: Toolchain → learner Android boot + staff Web boot. | N23: Toolchain → learner Android boot + staff Web boot. | O23: P1-T008..T010 | P23: P1-T008..T010 | Q23: P1-T008..T010 | R23: P1-T008..T010
B24: Hosted CI | C24: Hosted CI | D24: Hosted CI | E24: =VLOOKUP("P1-T011",'04_CONG_VIEC'!$A$5:$F$200,6,FALSE) -> BỊ CHẶN | H24: Có remote → chạy workflow từ clean checkout. | I24: Có remote → chạy workflow từ clean checkout. | J24: Có remote → chạy workflow từ clean checkout. | K24: Có remote → chạy workflow từ clean checkout. | L24: Có remote → chạy workflow từ clean checkout. | M24: Có remote → chạy workflow từ clean checkout. | N24: Có remote → chạy workflow từ clean checkout. | O24: P1-T011 | P24: P1-T011 | Q24: P1-T011 | R24: P1-T011
B25: Clean reproduction | C25: Clean reproduction | D25: Clean reproduction | E25: =VLOOKUP("P1-T012",'04_CONG_VIEC'!$A$5:$F$200,6,FALSE) -> BỊ CHẶN | H25: Clone sạch và chạy toàn stack. | I25: Clone sạch và chạy toàn stack. | J25: Clone sạch và chạy toàn stack. | K25: Clone sạch và chạy toàn stack. | L25: Clone sạch và chạy toàn stack. | M25: Clone sạch và chạy toàn stack. | N25: Clone sạch và chạy toàn stack. | O25: P1-T012 | P25: P1-T012 | Q25: P1-T012 | R25: P1-T012
B28: THỨ TỰ NÊN LÀM | C28: THỨ TỰ NÊN LÀM | D28: THỨ TỰ NÊN LÀM | E28: THỨ TỰ NÊN LÀM | F28: THỨ TỰ NÊN LÀM | G28: THỨ TỰ NÊN LÀM | H28: THỨ TỰ NÊN LÀM | I28: THỨ TỰ NÊN LÀM | J28: THỨ TỰ NÊN LÀM | K28: THỨ TỰ NÊN LÀM | L28: THỨ TỰ NÊN LÀM | M28: THỨ TỰ NÊN LÀM | N28: THỨ TỰ NÊN LÀM | O28: THỨ TỰ NÊN LÀM | P28: THỨ TỰ NÊN LÀM | Q28: THỨ TỰ NÊN LÀM | R28: THỨ TỰ NÊN LÀM
B29: # | C29: # | D29: Việc | E29: Việc | F29: Việc | G29: Việc | H29: Việc | I29: Việc | J29: Mục tiêu | K29: Mục tiêu | L29: Mục tiêu | M29: Mục tiêu | N29: Mục tiêu | O29: Mục tiêu | P29: Mục tiêu | Q29: Mục tiêu | R29: Mục tiêu
B30: 1 | C30: 1 | D30: Import + rerun V3.2 original | E30: Import + rerun V3.2 original | F30: Import + rerun V3.2 original | G30: Import + rerun V3.2 original | H30: Import + rerun V3.2 original | I30: Import + rerun V3.2 original | J30: Đóng nguồn chuẩn Phase 0 trong canonical repo. | K30: Đóng nguồn chuẩn Phase 0 trong canonical repo. | L30: Đóng nguồn chuẩn Phase 0 trong canonical repo. | M30: Đóng nguồn chuẩn Phase 0 trong canonical repo. | N30: Đóng nguồn chuẩn Phase 0 trong canonical repo. | O30: Đóng nguồn chuẩn Phase 0 trong canonical repo. | P30: Đóng nguồn chuẩn Phase 0 trong canonical repo. | Q30: Đóng nguồn chuẩn Phase 0 trong canonical repo. | R30: Đóng nguồn chuẩn Phase 0 trong canonical repo.
B31: 2 | C31: 2 | D31: PostgreSQL + migration + DB tests | E31: PostgreSQL + migration + DB tests | F31: PostgreSQL + migration + DB tests | G31: PostgreSQL + migration + DB tests | H31: PostgreSQL + migration + DB tests | I31: PostgreSQL + migration + DB tests | J31: Đóng runtime backend quan trọng nhất. | K31: Đóng runtime backend quan trọng nhất. | L31: Đóng runtime backend quan trọng nhất. | M31: Đóng runtime backend quan trọng nhất. | N31: Đóng runtime backend quan trọng nhất. | O31: Đóng runtime backend quan trọng nhất. | P31: Đóng runtime backend quan trọng nhất. | Q31: Đóng runtime backend quan trọng nhất. | R31: Đóng runtime backend quan trọng nhất.
B32: 3 | C32: 3 | D32: API readiness + Worker | E32: API readiness + Worker | F32: API readiness + Worker | G32: API readiness + Worker | H32: API readiness + Worker | I32: API readiness + Worker | J32: Chứng minh backend foundation chạy thật. | K32: Chứng minh backend foundation chạy thật. | L32: Chứng minh backend foundation chạy thật. | M32: Chứng minh backend foundation chạy thật. | N32: Chứng minh backend foundation chạy thật. | O32: Chứng minh backend foundation chạy thật. | P32: Chứng minh backend foundation chạy thật. | Q32: Chứng minh backend foundation chạy thật. | R32: Chứng minh backend foundation chạy thật.
B33: 4 | C33: 4 | D33: Flutter learner + staff | E33: Flutter learner + staff | F33: Flutter learner + staff | G33: Flutter learner + staff | H33: Flutter learner + staff | I33: Flutter learner + staff | J33: Chứng minh Android/Web chạy thật. | K33: Chứng minh Android/Web chạy thật. | L33: Chứng minh Android/Web chạy thật. | M33: Chứng minh Android/Web chạy thật. | N33: Chứng minh Android/Web chạy thật. | O33: Chứng minh Android/Web chạy thật. | P33: Chứng minh Android/Web chạy thật. | Q33: Chứng minh Android/Web chạy thật. | R33: Chứng minh Android/Web chạy thật.
B34: 5 | C34: 5 | D34: Hosted CI | E34: Hosted CI | F34: Hosted CI | G34: Hosted CI | H34: Hosted CI | I34: Hosted CI | J34: Chứng minh clean checkout chạy được. | K34: Chứng minh clean checkout chạy được. | L34: Chứng minh clean checkout chạy được. | M34: Chứng minh clean checkout chạy được. | N34: Chứng minh clean checkout chạy được. | O34: Chứng minh clean checkout chạy được. | P34: Chứng minh clean checkout chạy được. | Q34: Chứng minh clean checkout chạy được. | R34: Chứng minh clean checkout chạy được.
B35: 6 | C35: 6 | D35: Full clean reproduction | E35: Full clean reproduction | F35: Full clean reproduction | G35: Full clean reproduction | H35: Full clean reproduction | I35: Full clean reproduction | J35: Bằng chứng cuối trước khi đóng Phase 1. | K35: Bằng chứng cuối trước khi đóng Phase 1. | L35: Bằng chứng cuối trước khi đóng Phase 1. | M35: Bằng chứng cuối trước khi đóng Phase 1. | N35: Bằng chứng cuối trước khi đóng Phase 1. | O35: Bằng chứng cuối trước khi đóng Phase 1. | P35: Bằng chứng cuối trước khi đóng Phase 1. | Q35: Bằng chứng cuối trước khi đóng Phase 1. | R35: Bằng chứng cuối trước khi đóng Phase 1.
B38: Không cập nhật trạng thái blocker bằng tay ở đây. Các ô trạng thái được lấy từ 04_CONG_VIEC để giảm lệch dữ liệu. | C38: Không cập nhật trạng thái blocker bằng tay ở đây. Các ô trạng thái được lấy từ 04_CONG_VIEC để giảm lệch dữ liệu. | D38: Không cập nhật trạng thái blocker bằng tay ở đây. Các ô trạng thái được lấy từ 04_CONG_VIEC để giảm lệch dữ liệu. | E38: Không cập nhật trạng thái blocker bằng tay ở đây. Các ô trạng thái được lấy từ 04_CONG_VIEC để giảm lệch dữ liệu. | F38: Không cập nhật trạng thái blocker bằng tay ở đây. Các ô trạng thái được lấy từ 04_CONG_VIEC để giảm lệch dữ liệu. | G38: Không cập nhật trạng thái blocker bằng tay ở đây. Các ô trạng thái được lấy từ 04_CONG_VIEC để giảm lệch dữ liệu. | H38: Không cập nhật trạng thái blocker bằng tay ở đây. Các ô trạng thái được lấy từ 04_CONG_VIEC để giảm lệch dữ liệu. | I38: Không cập nhật trạng thái blocker bằng tay ở đây. Các ô trạng thái được lấy từ 04_CONG_VIEC để giảm lệch dữ liệu. | J38: Không cập nhật trạng thái blocker bằng tay ở đây. Các ô trạng thái được lấy từ 04_CONG_VIEC để giảm lệch dữ liệu. | K38: Không cập nhật trạng thái blocker bằng tay ở đây. Các ô trạng thái được lấy từ 04_CONG_VIEC để giảm lệch dữ liệu. | L38: Không cập nhật trạng thái blocker bằng tay ở đây. Các ô trạng thái được lấy từ 04_CONG_VIEC để giảm lệch dữ liệu. | M38: Không cập nhật trạng thái blocker bằng tay ở đây. Các ô trạng thái được lấy từ 04_CONG_VIEC để giảm lệch dữ liệu. | N38: Không cập nhật trạng thái blocker bằng tay ở đây. Các ô trạng thái được lấy từ 04_CONG_VIEC để giảm lệch dữ liệu. | O38: Không cập nhật trạng thái blocker bằng tay ở đây. Các ô trạng thái được lấy từ 04_CONG_VIEC để giảm lệch dữ liệu. | P38: Không cập nhật trạng thái blocker bằng tay ở đây. Các ô trạng thái được lấy từ 04_CONG_VIEC để giảm lệch dữ liệu. | Q38: Không cập nhật trạng thái blocker bằng tay ở đây. Các ô trạng thái được lấy từ 04_CONG_VIEC để giảm lệch dữ liệu. | R38: Không cập nhật trạng thái blocker bằng tay ở đây. Các ô trạng thái được lấy từ 04_CONG_VIEC để giảm lệch dữ liệu.
B39: Không cập nhật trạng thái blocker bằng tay ở đây. Các ô trạng thái được lấy từ 04_CONG_VIEC để giảm lệch dữ liệu. | C39: Không cập nhật trạng thái blocker bằng tay ở đây. Các ô trạng thái được lấy từ 04_CONG_VIEC để giảm lệch dữ liệu. | D39: Không cập nhật trạng thái blocker bằng tay ở đây. Các ô trạng thái được lấy từ 04_CONG_VIEC để giảm lệch dữ liệu. | E39: Không cập nhật trạng thái blocker bằng tay ở đây. Các ô trạng thái được lấy từ 04_CONG_VIEC để giảm lệch dữ liệu. | F39: Không cập nhật trạng thái blocker bằng tay ở đây. Các ô trạng thái được lấy từ 04_CONG_VIEC để giảm lệch dữ liệu. | G39: Không cập nhật trạng thái blocker bằng tay ở đây. Các ô trạng thái được lấy từ 04_CONG_VIEC để giảm lệch dữ liệu. | H39: Không cập nhật trạng thái blocker bằng tay ở đây. Các ô trạng thái được lấy từ 04_CONG_VIEC để giảm lệch dữ liệu. | I39: Không cập nhật trạng thái blocker bằng tay ở đây. Các ô trạng thái được lấy từ 04_CONG_VIEC để giảm lệch dữ liệu. | J39: Không cập nhật trạng thái blocker bằng tay ở đây. Các ô trạng thái được lấy từ 04_CONG_VIEC để giảm lệch dữ liệu. | K39: Không cập nhật trạng thái blocker bằng tay ở đây. Các ô trạng thái được lấy từ 04_CONG_VIEC để giảm lệch dữ liệu. | L39: Không cập nhật trạng thái blocker bằng tay ở đây. Các ô trạng thái được lấy từ 04_CONG_VIEC để giảm lệch dữ liệu. | M39: Không cập nhật trạng thái blocker bằng tay ở đây. Các ô trạng thái được lấy từ 04_CONG_VIEC để giảm lệch dữ liệu. | N39: Không cập nhật trạng thái blocker bằng tay ở đây. Các ô trạng thái được lấy từ 04_CONG_VIEC để giảm lệch dữ liệu. | O39: Không cập nhật trạng thái blocker bằng tay ở đây. Các ô trạng thái được lấy từ 04_CONG_VIEC để giảm lệch dữ liệu. | P39: Không cập nhật trạng thái blocker bằng tay ở đây. Các ô trạng thái được lấy từ 04_CONG_VIEC để giảm lệch dữ liệu. | Q39: Không cập nhật trạng thái blocker bằng tay ở đây. Các ô trạng thái được lấy từ 04_CONG_VIEC để giảm lệch dữ liệu. | R39: Không cập nhật trạng thái blocker bằng tay ở đây. Các ô trạng thái được lấy từ 04_CONG_VIEC để giảm lệch dữ liệu.

Sheet 02_SAN_PHAM
A1: SẢN PHẨM MINGO — NGHIỆP VỤ & LUẬT HỆ THỐNG
A2: Đọc sheet này trước khi code nghiệp vụ. Từ kỹ thuật được giữ trong ngoặc khi cần, nhưng ưu tiên diễn đạt dễ hiểu bằng tiếng Việt.
A4: TÓM TẮT 4 ĐIỀU CẦN NHỚ
A5: 1 | B5: Mingo học theo bằng chứng | C5: Không biến streak/click/skip thành mastery.
A6: 2 | B6: Máy chủ là nguồn quyết định chính | C6: Client gửi hành động/dữ liệu quan sát; server quyết định điểm, tiến độ, quyền.
A7: 3 | B7: Offline không được tạo dữ liệu trùng | C7: Command và telemetry tách riêng; retry phải idempotent.
A8: 4 | B8: ML là lớp tăng cường | C8: Không có ML/recommendation thì sản phẩm vẫn phải học được.
A10: 1. MINGO LÀ GÌ?
A11: Mingo là nền tảng học ngôn ngữ thích ứng, khởi đầu với tiếng Anh. Người học đi qua các chu kỳ học ngắn (Learning Cycle) có mục tiêu học rõ ràng, hoạt động tự nhớ/truy xuất (Retrieval), phản hồi và bài kiểm tra độc lập (Check). Hệ thống lưu bằng chứng học tập theo thời gian, hỗ trợ offline, và chỉ sau khi dữ liệu sản phẩm đủ đáng tin mới bổ sung Learning Intelligence → Risk Prediction → Recommendation/Intervention. Mingo phải vẫn hoạt động được khi ML/recommendation bị tắt.
A15: 2. LUỒNG LEARNER CỐT LÕI
A16: Bước | B16: Nghiệp vụ | C16: Hệ thống làm gì
A17: 1 | B17: Mở app | C17: Người học vào Mingo; có thể chọn mục tiêu cá nhân.
A18: 2 | B18: Placement ngắn hoặc bỏ qua | C18: Tạo trạng thái bắt đầu tạm thời (provisional); không ép placement dài.
A19: 3 | B19: Chọn mục tiêu học / chu kỳ học | C19: Backend chọn nội dung đủ điều kiện theo curriculum, review, focus và prerequisite.
A20: 4 | B20: Review | C20: Ôn đúng thứ cần ôn; không tạo infinite scroll.
A21: 5 | B21: Learn | C21: Giải thích/ngữ cảnh ngắn phù hợp Vocabulary, Grammar hoặc Listening.
A22: 6 | B22: Retrieve | C22: Người học phải tự nhớ/trả lời; đây là bằng chứng quan trọng.
A23: 7 | B23: Transfer | C23: Dùng kiến thức trong ngữ cảnh khác.
A24: 8 | B24: Check | C24: Bài kiểm tra độc lập; server là nguồn quyết định điểm chính.
A25: 9 | B25: Feedback + lưu evidence | C25: Giữ đúng first response, retry, hint, skip và điều kiện assessment.
A26: 10 | B26: Kết thúc cycle | C26: Có điểm dừng rõ; người học chọn tiếp tục hoặc dừng.
A27: 11 | B27: Tích lũy theo thời gian | C27: Review scheduler và analytics tích lũy; intelligence/risk/recommendation đến ở phase sau.
A30: 3. NHỮNG LUẬT RẤT DỄ LÀM SAI
A31: Chủ đề | B31: Luật dễ hiểu
